<?xml version="1.0"?>
<robot name="wheel" xmlns:xacro="http://www.ros.org/wiki/xacro">
 
 
  <xacro:macro name="wheel" params="prefix fb lr parent translateX translateY translateZ wheel_radius wheel_height flip"> <!--fb : front, back ; lr: left, right -->
    <link name="${prefix}${fb}_${lr}_wheel">
      <visual>
        <origin xyz="0 0 0" rpy="${flip*pi/2} 0 0" /> 
        <geometry>
          <cylinder length="${wheel_height}" radius="${wheel_radius}" />
        </geometry>
        <material name="Black" />
      </visual>
      <collision>
        <origin xyz="0 0 0" rpy="${flip*pi/2} 0 0" />
        <geometry>
          <cylinder length="${wheel_height}" radius="${wheel_radius}" />
        </geometry>
      </collision>
      <inertial>
        <mass value="${wheel_mass}" />
        <!-- <origin xyz="0 0 0" rpy="${flip*pi/2} 0 0"/> -->
        <origin xyz="0 0 0" />
        <xacro:cylinder_inertia  m="${wheel_mass}" r="${wheel_radius}" h="${wheel_height}" />
      </inertial>
    </link>
 
    <gazebo reference="${prefix}${fb}_${lr}_wheel">
      <mu1 value="100.0"/>
      <mu2 value="100.0"/>
      <kp  value="10000000.0" />
      <kd  value="1.0" />
      <fdir1 value="1 0 0"/>
      <material>Gazebo/Black</material>
      <turnGravityOff>false</turnGravityOff>
    </gazebo>
 
    <joint name="${prefix}${fb}_${lr}_wheel_joint" type="continuous">
      <parent link="${prefix}${parent}"/>
      <child link="${prefix}${fb}_${lr}_wheel"/>
      <origin xyz="${translateX} ${translateY} ${translateZ}" rpy="0 0 0" /> 
      <axis xyz="0 1 0" rpy="0 0 0" />
      <limit effort="1000" velocity="100"/>
      <joint_properties damping="0.0" friction="0.0"/>
    </joint>
 
    <!-- Transmission is important to link the joints and the controller -->
    <transmission name="${prefix}${fb}_${lr}_wheel_joint_trans">
      <type>transmission_interface/SimpleTransmission</type>
      <joint name="${prefix}${fb}_${lr}_wheel_joint">
        <hardwareInterface>EffortJointInterface</hardwareInterface>
      </joint>
      <actuator name="${prefix}${fb}_${lr}_wheel_joint_motor">
        <hardwareInterface>EffortJointInterface</hardwareInterface>
        <mechanicalReduction>1</mechanicalReduction>
      </actuator>
    </transmission>
 
  </xacro:macro>
</robot>
